Workbook
Name NativeTimeline_date: #N/A
Name Slicer_category: #N/A
Name Slicer_Customer_Type: #N/A
Name Slicer_region: #N/A

Sheet Raw_Data
A1: Invoice_ID | B1: date | C1: category | D1: sku | E1: region | F1: channel | G1: price | H1: quantity | I1: discount | J1: revenue | K1: Cost_Per_Unit | L1: Profit | M1: Customer_Type | N1: Payment_Method | O1: Promotion | P1: Month | Q1: Year | R1: Gross_Sales | S1: Discount_Value | T1: Calculated_Net_Sales | U1: Profit_Margin
A2: INV-00001 | B2: 44927 | C2: Snacks | D2: SN-007 | E2: Shiraz | F2: Pharmacy | G2: 55904.04 | H2: 6 | I2: 4 | J2: 335424.22 | K2: 45971.6 | L2: 59594.62 | M2: Retail | N2: Card | O2: No | P2: 1 | Q2: 2023 | R2: =Raw_Data!$G2*Raw_Data!$H2 -> 335424.24 | S2: =Raw_Data!$R2*Raw_Data!$I2/100 -> 13416.97 | T2: =Raw_Data!$R2-Raw_Data!$S2 -> 322007.27 | U2: =Raw_Data!$L2/Raw_Data!$J2 -> 0.1776694
A3: INV-00002 | B3: 44927 | C3: Dairy | D3: DA-009 | E3: Tehran | F3: Online | G3: 101091.2 | H3: 6 | I3: 14.83 | J3: 606547.17 | K3: 79755.67 | L3: 128013.13 | M3: Retail | N3: Transfer | O3: Yes | P3: 1 | Q3: 2023 | R3: =Raw_Data!$G3*Raw_Data!$H3 -> 606547.2 | S3: =Raw_Data!$R3*Raw_Data!$I3/100 -> 89950.95 | T3: =Raw_Data!$R3-Raw_Data!$S3 -> 516596.25 | U3: =Raw_Data!$L3/Raw_Data!$J3 -> 0.21105223
A4: INV-00003 | B4: 44928 | C4: Snacks | D4: SN-100 | E4: Tehran | F4: Wholesale | G4: 67767.29 | H4: 4 | I4: 2.38 | J4: 271069.16 | K4: 59210.44 | L4: 34227.4 | M4: Retail | N4: Card | O4: No | P4: 1 | Q4: 2023 | R4: =Raw_Data!$G4*Raw_Data!$H4 -> 271069.16 | S4: =Raw_Data!$R4*Raw_Data!$I4/100 -> 6451.446 | T4: =Raw_Data!$R4-Raw_Data!$S4 -> 264617.71 | U4: =Raw_Data!$L4/Raw_Data!$J4 -> 0.12626815
A5: INV-00004 | B5: 44928 | C5: Beverages | D5: BE-135 | E5: Shiraz | F5: Pharmacy | G5: 70094.95 | H5: 56 | I5: 1.77 | J5: 3925317 | K5: 53186.02 | L5: 946899.68 | M5: Corporate | N5: Card | O5: No | P5: 1 | Q5: 2023 | R5: =Raw_Data!$G5*Raw_Data!$H5 -> 3925317.2 | S5: =Raw_Data!$R5*Raw_Data!$I5/100 -> 69478.114 | T5: =Raw_Data!$R5-Raw_Data!$S5 -> 3855839.1 | U5: =Raw_Data!$L5/Raw_Data!$J5 -> 0.24122884
A6: INV-00005 | B6: 44928 | C6: Dairy | D6: DA-110 | E6: Shiraz | F6: Online | G6: 104608.72 | H6: 7 | I6: 3.72 | J6: 732261.06 | K6: 75751.96 | L6: 201997.32 | M6: Retail | N6: Transfer | O6: No | P6: 1 | Q6: 2023 | R6: =Raw_Data!$G6*Raw_Data!$H6 -> 732261.04 | S6: =Raw_Data!$R6*Raw_Data!$I6/100 -> 27240.111 | T6: =Raw_Data!$R6-Raw_Data!$S6 -> 705020.93 | U6: =Raw_Data!$L6/Raw_Data!$J6 -> 0.27585424
A7: INV-00006 | B7: 44928 | C7: Personal Care | D7: PE-067 | E7: Mashhad | F7: Hypermarket | G7: 110481.45 | H7: 32 | I7: 4.47 | J7: 3535406.3 | K7: 84856.94 | L7: 819984.39 | M7: Corporate | N7: Transfer | O7: No | P7: 1 | Q7: 2023 | R7: =Raw_Data!$G7*Raw_Data!$H7 -> 3535406.4 | S7: =Raw_Data!$R7*Raw_Data!$I7/100 -> 158032.67 | T7: =Raw_Data!$R7-Raw_Data!$S7 -> 3377373.7 | U7: =Raw_Data!$L7/Raw_Data!$J7 -> 0.23193498
A8: INV-00007 | B8: 44928 | C8: Beverages | D8: BE-027 | E8: Shiraz | F8: Online | G8: 52312.42 | H8: 1 | I8: 14.12 | J8: 52312.42 | K8: 39970.35 | L8: 12342.07 | M8: Retail | N8: POS | O8: Yes | P8: 1 | Q8: 2023 | R8: =Raw_Data!$G8*Raw_Data!$H8 -> 52312.42 | S8: =Raw_Data!$R8*Raw_Data!$I8/100 -> 7386.5137 | T8: =Raw_Data!$R8-Raw_Data!$S8 -> 44925.906 | U8: =Raw_Data!$L8/Raw_Data!$J8 -> 0.23593001
A9: INV-00008 | B9: 44928 | C9: Home Care | D9: HO-108 | E9: Ahvaz | F9: Pharmacy | G9: 57049.91 | H9: 1 | I9: 3.35 | J9: 57049.91 | K9: 48137.17 | L9: 8912.75 | M9: Retail | N9: Transfer | O9: No | P9: 1 | Q9: 2023 | R9: =Raw_Data!$G9*Raw_Data!$H9 -> 57049.91 | S9: =Raw_Data!$R9*Raw_Data!$I9/100 -> 1911.172 | T9: =Raw_Data!$R9-Raw_Data!$S9 -> 55138.738 | U9: =Raw_Data!$L9/Raw_Data!$J9 -> 0.15622724
A10: INV-00009 | B10: 44928 | C10: Dairy | D10: DA-006 | E10: Tehran | F10: Pharmacy | G10: 97977.53 | H10: 4 | I10: 3.41 | J10: 391910.1 | K10: 76665.8 | L10: 85246.91 | M10: Retail | N10: Transfer | O10: No | P10: 1 | Q10: 2023 | R10: =Raw_Data!$G10*Raw_Data!$H10 -> 391910.12 | S10: =Raw_Data!$R10*Raw_Data!$I10/100 -> 13364.135 | T10: =Raw_Data!$R10-Raw_Data!$S10 -> 378545.98 | U10: =Raw_Data!$L10/Raw_Data!$J10 -> 0.21751649
A11: INV-00010 | B11: 44929 | C11: Personal Care | D11: PE-123 | E11: Tehran | F11: Wholesale | G11: 110259.64 | H11: 6 | I11: 4.55 | J11: 661557.81 | K11: 86484.54 | L11: 142650.55 | M11: Retail | N11: Card | O11: No | P11: 1 | Q11: 2023 | R11: =Raw_Data!$G11*Raw_Data!$H11 -> 661557.84 | S11: =Raw_Data!$R11*Raw_Data!$I11/100 -> 30100.882 | T11: =Raw_Data!$R11-Raw_Data!$S11 -> 631456.96 | U11: =Raw_Data!$L11/Raw_Data!$J11 -> 0.21562825
A12: INV-00011 | B12: 44930 | C12: Beverages | D12: BE-121 | E12: Tabriz | F12: Supermarket | G12: 72509.9 | H12: 9 | I12: 6.28 | J12: 652589.12 | K12: 50660.02 | L12: 196648.94 | M12: Retail | N12: Card | O12: Yes | P12: 1 | Q12: 2023 | R12: =Raw_Data!$G12*Raw_Data!$H12 -> 652589.1 | S12: =Raw_Data!$R12*Raw_Data!$I12/100 -> 40982.595 | T12: =Raw_Data!$R12-Raw_Data!$S12 -> 611606.5 | U12: =Raw_Data!$L12/Raw_Data!$J12 -> 0.30133653
A13: INV-00012 | B13: 44930 | C13: Beverages | D13: BE-109 | E13: Mashhad | F13: Supermarket | G13: 68825.13 | H13: 11 | I13: 5.14 | J13: 757076.41 | K13: 49080.04 | L13: 217195.96 | M13: Retail | N13: Cash | O13: No | P13: 1 | Q13: 2023 | R13: =Raw_Data!$G13*Raw_Data!$H13 -> 757076.43 | S13: =Raw_Data!$R13*Raw_Data!$I13/100 -> 38913.729 | T13: =Raw_Data!$R13-Raw_Data!$S13 -> 718162.7 | U13: =Raw_Data!$L13/Raw_Data!$J13 -> 0.28688777
... A5001: INV-05000 | B5001: 46022 | C5001: Snacks | D5001: SN-123 | E5001: Mashhad | F5001: Hypermarket | G5001: 58305.46 | H5001: 6 | I5001: 4.31 | J5001: 349832.74 | K5001: 39191.71 | L5001: 114682.5 | M5001: Retail | N5001: Cash | O5001: No | P5001: 12 | Q5001: 2025 | R5001: =Raw_Data!$G5001*Raw_Data!$H5001 -> 349832.76 | S5001: =Raw_Data!$R5001*Raw_Data!$I5001/100 -> 15077.792 | T5001: =Raw_Data!$R5001-Raw_Data!$S5001 -> 334754.97 | U5001: =Raw_Data!$L5001/Raw_Data!$J5001 -> 0.32782095

Sheet Calculated_Fields
A1: field name
A2: Gross_Sales
A3: Discount_Value
A4: Calculated_Net_Sales
A5: Profit_Margin

Sheet Pivot_KPIs
A1: Sum of revenue | B1: Sum of Profit | C1: Sum of quantity | D1: Average of Profit_Margin | F1: category | G1: Sum of revenue | H1: Sum of Profit | J1: Row Labels | K1: Sum of revenue | L1: Sum of Profit
A2: 9.4661818e+09 | B2: 2.206801e+09 | C2: 122964 | D2: 0.23408227 | F2: Beverages | G2: 1.6763372e+09 | H2: 3.9621846e+08 | J2: Ahvaz | K2: 1.6728821e+09 | L2: 4.0029454e+08
F3: Dairy | G3: 2.5291143e+09 | H3: 5.860112e+08 | J3: Isfahan | K3: 1.4733164e+09 | L3: 3.4261507e+08
F4: Home Care | G4: 1.2162917e+09 | H4: 2.8881986e+08 | J4: Mashhad | K4: 1.5377331e+09 | L4: 3.5338226e+08
F5: Personal Care | G5: 2.5072008e+09 | H5: 5.7525161e+08 | J5: Shiraz | K5: 1.7824259e+09 | L5: 4.1054197e+08
F6: Snacks | G6: 1.5372377e+09 | H6: 3.6049983e+08 | J6: Tabriz | K6: 1.446464e+09 | L6: 3.440906e+08
F7: Grand Total | G7: 9.4661818e+09 | H7: 2.206801e+09 | J7: Tehran | K7: 1.5533603e+09 | L7: 3.5587651e+08
J8: Grand Total | K8: 9.4661818e+09 | L8: 2.206801e+09
A26: Row Labels | B26: Sum of revenue | C26: Sum of Profit | I26: Row Labels | J26: Sum of revenue | K26: Sum of Profit
A27: Hypermarket | B27: 1.9507729e+09 | C27: 5.4154405e+08 | I27: 2025 | J27: 3.1831993e+09 | K27: 7.4050912e+08
A28: Online | B28: 1.591139e+09 | C28: 3.6944085e+08 | I28: 7 | J28: 4.1660776e+08 | K28: 93110955
A29: Pharmacy | B29: 1.4774711e+09 | C29: 2.964299e+08 | I29: 3 | J29: 3.2750144e+08 | K29: 82653678
A30: Supermarket | B30: 1.8788491e+09 | C30: 5.6426164e+08 | I30: 5 | J30: 3.0408676e+08 | K30: 65717895
A31: Wholesale | B31: 2.5679496e+09 | C31: 4.3512452e+08 | I31: 11 | J31: 2.9613679e+08 | K31: 69215995
A32: Grand Total | B32: 9.4661818e+09 | C32: 2.206801e+09 | I32: 4 | J32: 2.8193045e+08 | K32: 65312694
I33: 12 | J33: 2.5850558e+08 | K33: 62876972
I34: 10 | J34: 2.4970823e+08 | K34: 60160723
I35: 6 | J35: 2.2604277e+08 | K35: 52401410
I36: 9 | J36: 2.1673108e+08 | K36: 53162329
I37: 8 | J37: 2.1382046e+08 | K37: 47966133
I38: 1 | J38: 2.1376403e+08 | K38: 48699715
I39: 2 | J39: 1.7836395e+08 | K39: 39230619
I40: 2024 | J40: 3.139687e+09 | K40: 7.3804213e+08
I41: 8 | J41: 3.1533979e+08 | K41: 75234298
I42: 11 | J42: 2.8872864e+08 | K42: 68258853
I43: 4 | J43: 2.7903494e+08 | K43: 63182088
I44: 3 | J44: 2.7400008e+08 | K44: 64145962
A45: Row Labels | B45: Sum of revenue | C45: Sum of Profit | I45: 6 | J45: 2.6763858e+08 | K45: 64028975 | M45: Row Labels | N45: Sum of revenue | O45: Sum of Profit | P45: Average of Profit_Margin
A46: No | B46: 7.3048031e+09 | C46: 1.6990505e+09 | I46: 5 | J46: 2.6621805e+08 | K46: 60745004 | M46: 0 | N46: 14697264 | O46: 3772116.6 | P46: 0.25231843
A47: Yes | B47: 2.1613786e+09 | C47: 5.0775045e+08 | I47: 10 | J47: 2.6294878e+08 | K47: 63004744 | M47: 0.01 | N47: 8426418.6 | O47: 1771053.9 | P47: 0.21668121
A48: Grand Total | B48: 9.4661818e+09 | C48: 2.206801e+09 | I48: 1 | J48: 2.5949604e+08 | K48: 60604912 | M48: 0.02 | N48: 24593782 | O48: 5558978.5 | P48: 0.2123614
I49: 12 | J49: 2.5936671e+08 | K49: 68909302 | M49: 0.03 | N49: 5369467.9 | O49: 998529.64 | P49: 0.21775425
I50: 9 | J50: 2.3565036e+08 | K50: 51562022 | M50: 0.04 | N50: 15706054 | O50: 2979279.4 | P50: 0.19602842
I51: 7 | J51: 2.2907156e+08 | K51: 50793795 | M51: 0.05 | N51: 6272278 | O51: 1679463.1 | P51: 0.25989674
I52: 2 | J52: 2.0219347e+08 | K52: 47572170 | M52: 0.06 | N52: 2824991.4 | O52: 694851.27 | P52: 0.23044637
I53: 2023 | J53: 3.1432955e+09 | K53: 7.2824971e+08 | M53: 0.07 | N53: 3645030.4 | O53: 682128.86 | P53: 0.21516444
I54: 12 | J54: 3.4014326e+08 | K54: 75076968 | M54: 0.08 | N54: 9794379.9 | O54: 2198381 | P54: 0.22437266
I55: 11 | J55: 2.9863905e+08 | K55: 71317276 | M55: 0.09 | N55: 4665753.4 | O55: 792875.19 | P55: 0.18531567
I56: 9 | J56: 2.9378456e+08 | K56: 69153093 | M56: 0.11 | N56: 3665559.5 | O56: 1069515 | P56: 0.28919421
I57: 5 | J57: 2.907943e+08 | K57: 67627896 | M57: 0.12 | N57: 6613701.7 | O57: 1561742.5 | P57: 0.23210141
...

Sheet QA_Check
A1: Revenue Check | B1: Mismatch
A2: Negative Profit | B2: =IF(COUNTIF(SALES_DATA[Profit], "<0")=0, "OK", "Found Negative Profit") -> OK
A3: Max Profit | B3: =MAX(SALES_DATA[Profit]) -> 5150517.7
A4: Min Profit | B4: =MIN(SALES_DATA[Profit]) -> 6116.58
A5: Min Revenue | B5: =MIN(SALES_DATA[revenue]) -> 38398.19
A6: Max Revenue | B6: =MAX(SALES_DATA[revenue]) -> 18346547
A7: Total Orders | B7: =ROWS(SALES_DATA[]) -> 5000
